## try...catch

**`try...catch` 语法**

```JavaScript
try {
  // 代码...
} catch (err) {
  // 错误捕获
}
```

执行顺序：

1. 执行 `try {...}` 中的代码
2. 如果这里没有错误，则忽略 `catch(err)`
3. 如果这里出现错误，则 `try` 执行停止，跳转到 `catch(err)` 的开头。变量 `err` 将包含一个 `error` 对象，包含了所发生事件的详细信息

`try...catch` 本身的错误叫解析错误，无法处理，`try` 内部的错误叫运行时错误，才能被正确处理

`try...catch` 只能捕获同步的错误，异步错误不能捕获

```JavaScript
try {
  setTimeout(function() {
    noSuchVariable; // 这里有错
  }, 1000);
} catch (e) {
  console.log( "won't work" );
}
```

**Error 对象**

内建 `Error` 对象的属性

主要属性

- `name`：`Error` 名称，例：`ReferenceError`
- `message`：关于 `error` 的详细文字描述

非标准属性

- `stack`：当前的调用栈

```JavaScript
try {
  lalala; // error
} catch(err) {
  console.log(err.name); // ReferenceError
  console.log(err.message); // lalala is not defined
  console.log(err.stack); // ReferenceError: lalala is not defined at (...call stack)

  console.log(err); // ReferenceError: lalala is not defined
}
```

`error` 是可选的

```JavaScript
try {
  // ...
} catch {
  // ...
}
```

实例：解析服务器的数据

如果 `json` 格式错误，`JSON.parse` 就会生成一个 `error`

```JavaScript
let json = "{ bad json }";

try {
  let user = JSON.parse(json); // 出现 error
  console.log( user.name ); // 不工作
} catch (e) {
  // 跳转到这里并继续执行
  console.log( "the data has errors" );
  console.log( e.name );
  console.log( e.message );
}
```

## 抛出自定义 `error`

使用 `throw` 操作符抛出错误，`throw` 操作符后可跟任何东西，但一般是对象，并具有 `name` 和 `message`

内建错误构造器

- `Error`
- `SyntaxError`
- `ReferenceError`
- `TypeError` 等

```JavaScript
let error = new Error(message);
let error = new SyntaxError(message);
let error = new ReferenceError(message);
```

错误的 `name` 就是构造器的名字，错误的 `message` 是传入的字符串

对上面代码，如果 `json` 数据没有我们想要的 `name` 属性，则抛出错误

```JavaScript
let json = '{ "age": 30 }'; // 不完整的数据

try {
  let user = JSON.parse(json); // 没有 error
  if (!user.name) {
    throw new SyntaxError("Incomplete data: no name");
  }
  console.log( user.name );
} catch(e) {
  console.log( "JSON Error: " + e.message ); // JSON Error: Incomplete data: no name
}
```

**再次抛出**

`catch` 应该只处理它知道的 `error`，并抛出所有其他 `error`

```JavaScript
let json = '{ "age": 30 }'; // 不完整的数据
try {
  let user = JSON.parse(json);
  if (!user.name) {
    throw new SyntaxError("Incomplete data: no name");
  }
  blabla(); // 预料之外的 error
  console.log( user.name );
} catch(e) {
  if (e instanceof SyntaxError) {
    console.log( "JSON Error: " + e.message );
  } else {
    throw e; // 再次抛出
  }
}
```

这里 `catch` 只处理 `SyntaxError` 类型的错误，其他错误会被抛出，也许会被再外面所捕获

```JavaScript
function readData() {
  let json = '{ "age": 30 }';
  try {
    blabla(); // error
  } catch (e) {
    if (!(e instanceof SyntaxError)) {
      throw e; // 再次抛出（不知道如何处理它）
    }
  }
}

try {
  readData();
} catch (e) {
  console.log( "External catch got: " + e ); // 捕获了它！
}
```

**try...catch...finally**

语法

```JavaScript
try {
   ... 尝试执行的代码 ...
} catch(e) {
   ... 处理 error ...
} finally {
   ... 总是会执行的代码 ...
}
```

适用场景

当我们开始做某事的时候，希望无论出现什么情况都要完成完成某个任务

一个函数中返回不是立即停止的例子，一旦进入 `try`，必须执行完

```JavaScript
function func() {
  try {
    return 1;
  } catch (e) {
  } finally {
    console.log( 'finally' );
  }
}

console.log( func() ); // 先执行 finally 中的 log，然后执行这个 log
```

`catch` 语段也可以去除，即不处理错误，但在出错后不立即停止，而是再执行一段

**全局 `catch`**

用于在发生未捕获的 error 时执行

- `Node.js`：`process.on("uncaughtException")`

- `Browser`：`window.onerror`

语法

```JavaScript
/**
 * message: Error 信息
 * url：发生 error 的脚本的 URL
 * line，col：发生 error 处的代码的行号和列号
 * error：Error 对象
 */
window.onerror = function(message, url, line, col, error) {};
```

示例

```JavaScript
  window.onerror = function(message, url, line, col, error) {
    console.log(`${message}\n At ${line}:${col} of ${url}`);
  };

  function readData() {
    badFunc(); // 出问题了
  }

  readData();
```

## 自定义 Error，扩展 Error

例：`HttpError`、`DbError`、`NotFoundError`

自定义验证错误类：`ValidationError` 代表 `json` 格式正确，但没有所必须的字段，或者字段的格式错误

```JavaScript
// 内建的 Error 类的伪代码
class Error {
  constructor(message) {
    this.message = message;
    this.name = "Error"; // 不同的内建 error 类有不同的名字
    this.stack = <call stack>;
  }
}
```

继承内建 `Error`

```JavaScript
class ValidationError extends Error {
  constructor(message) {
    super(message);
    this.name = "ValidationError";
  }
}
```

抛出错误的函数

```JavaScript
function readUser(json) {
  let user = JSON.parse(json);
  if (!user.age) {
    throw new ValidationError("No field: age");
  }
  if (!user.name) {
    throw new ValidationError("No field: name");
  }
  return user;
}
```

使用 `try...catch` 捕获错误

```JavaScript
try {
  let user = readUser('{ "age": 25 }');
} catch(err) {
  if (err instanceof ValidationError) {
    console.log("Invalid data: " + err.message); // Invalid data: No field: name
  } else if (err instanceof SyntaxError) {
    console.log("JSON Syntax Error: " + err.message);
  } else {
    throw err; // 未知的 error，再次抛出
  }
}
```

**深入继承**

再次继承的属性缺失 `Error`

```JavaScript
class PropertyRequiredError extends ValidationError {
  constructor(property) {
    super("No property: " + property);
    this.name = "PropertyRequiredError";
    this.property = property;
  }
}
```

使用

```JavaScript
function validateUser(user) {
  if (!user.age) {
    throw new PropertyRequiredError("age");
  }
  if (!user.name) {
    throw new PropertyRequiredError("name");
  }
}
```

每次继承的类都要手动赋值 `name`，但是我们知道 `name` 其实就是构造器的名字，所以我们可以自定义一个基类，`name` 值就赋值为构造器的名字

```JavaScript
class MyError extends Error {
  constructor(message) {
    super(message);
    this.name = this.constructor.name;
  }
}

class ValidationError extends MyError {}
```

**包装异常**

每次都一一检查所有的 error 类型将是非常繁琐的，也不是必须的

所以我们应该再抽象一层

步骤：

1. 创建一个新的类 `ReadError` 来表示一般的**数据读取** `error`

   ```JavaScript
   class ReadError extends Error {
     constructor(message, cause) {
       super(message);
       this.name = 'ReadError';
       this.cause = cause;
     }
   }
   ```

2. 函数 `readUser` 将捕获内部发生的数据读取 `error`，例如 `ValidationError` 和 `SyntaxError`，并生成一个 `ReadError` 来进行替代。

   ```JavaScript
   function readUser(json) {
     let user;
     try {
       user = JSON.parse(json);
     } catch (err) {
       if (err instanceof SyntaxError) {
         throw new ReadError("Syntax Error", err);
       } else {
         throw err;
       }
     }
     try {
       validateUser(user);
     } catch (err) {
       if (err instanceof ValidationError) {
         throw new ReadError("Validation Error", err);
       } else {
         throw err;
       }
     }

   }
   ```

3. 对象 `ReadError` 会把对原始 `error` 的引用保存在其 `cause` 属性中。

   ```JavaScript
   try {
     readUser('{bad json}');
   } catch (e) {
     if (e instanceof ReadError) {
       console.log(e);
       console.log("Original error: " + e.cause);
     } else {
       throw e;
     }
   }
   ```

调用 `readUser` 的代码只需要检查 `ReadError`，而不必检查每种数据读取 `error`。并且，如果需要更多 `error` 细节，那么可以检查 `readUser` 的 `cause` 属性

[完整代码](./readJsonError.js)

> Tips：一般用 `instanceof` 检查特定 `Error`，但有时有来自第三方库的 `error` 对象，并且没有简单的方法来获取它的类。那么可以用 `name` 属性检查
